Workbook

Sheet Intro
B2: Audit Day Justification (ADJ) for ISO 9001, ISO 14001 and/or ISO 45001
B3: ='Revision History'!B10 -> Version 2.2
B5: Intent of Use:
B7: Auditors shall use the present file to calculate audit days for the upcoming Certification Cycle (i.e. CR & SVs visits), or in case any interim changes have taken place, whereas Sales colleagues need to use this for any new Opportunity (i.e. IA, CTA, ToA) for certifications on our Core products (i.e. ISO 9001, ISO 14001 and/or ISO 45001). The purpose of this is to ensure that the correct information needed is collected and validated: - for the completion of the Technical Review, - the provision of proper justification for Accreditation purposes, - to have realistic and correct information in our systems, and - to update the contract(s) between LRQA and the clients. Therefore, it is crucial that Sales enter the information as provided by the client while Auditors confirm this information with the clients, as a minimum, during the Focus Visit.
B10: Using the file:
B12: For your convenience, start entering information in the sheets following from left to right tabs. All information in 'Client Info' sheet shall be completed in full in order for the other sheets to be filled in automatically.
B13: In the 'Client Info' tab you shall enter the information applicable to the Client (i.e. applicable Products, Codes, ), including all Sites (e.g. site name, address, whatever will distinguish the site), marking the applicable Standards with 'Yes' in the corresponding columns.
B15: Clarifications: The cells that cannot be modified are greyed out, whereas the cells that need your input are color tinted. ALWAYS use a new file from the template; do NOT use an existing file from another client and 'Save as...'.
B16: Furthermore, throughout this file, you will see at several points text showing in Dark Mint color; note that this is automatically calculated and cannot be changed.
B18: For guidance on how to correctly complete the ADJ, please click on the icons and refer to the training guides available:
B22: Naming the file:
B24: When it comes to under which name the file shall be saved, note that the file name will need to begin with the letters ADJ, followed by anything else. You can include descriptive information, such as - for Auditors, the BOS Contract ID, the Job Number, the visit type etc., - for Sales, the Company Name, Opportunity Type, etc. as there is not limitation on this. But, you DEFINITELY need to use the ADJ letters as a prefix. For example, the file can be stored under the name structure since it starts with 'ADJ':
B25: ADJ_[BOSContractID]_[JobNo]_[VisitType].xlsx
B27: Mandatory!
... B47: Click here to Start

Sheet Client Info
B1: Client Information
B3: For your convenience, start entering information in tabs from left to right. Information in the present sheet shall be completed in full in order for the other sheets to be filled in automatically! Clarifications: The cells that cannot be modified are greyed out, whereas the cells that need your input are color tinted. ALWAYS use a new file from the template; do NOT use an existing file from another client and 'Save as...'.
B5: Cell color description: | C5: Input (mandatory) | D5: Input (optional) | E5: Output (automatically calculated) | F5: Errors (entries need to be fixed) | G5: Link to follow for Guidance
B7: Throughout this file, you will see at several points text showing in italic format and in grey color. These are Notes that will help you by providing clarifications of the nearby cells
B8: If text showing in Dark Mint color, note that this is automatically calculated and cannot be changed.
B9: If text showing in Coral color, then this area needs attention.
B11: Please enter the basic information below, which you should already have (from the Job Note, etc):
B14: Report Data
B16: Date created: | E16: Created by:
F17: Enter (Team) Lead Auditor name / Sales Opportunity Owner
B18: Client Details
B20: Client/Account name: | E20: BOS Contract Number ID: (for existing clients)
B22: Any special comments for this Account(s)? | E22: Opportunity Name/link: (only for Sales)
B25: Standard(s): | C25: Mark as applicable with "Yes" | D25: Risk/Complexity | E25: Reason for selection of Risk/Complexity:
B26: ISO 9001 | E26: =IF(C26="YES","As per MD 5","")
B27: ISO 14001 | E27: =IF(C27="YES","As per MD 5","")
B28: ISO 45001 | E28: =IF(C28="YES","As per MD 5","")
D29: =IF(OR(D26="High",D27="High",D28="High"),"If Complexity/Risk is set to High, don't forget to add Adjustment Factors that increase audit time! (see Adjustment Factors tab)","")
B30: Notes:
B31: Complexity/Risk category shall be determined based on MD5, Annexes 1, 2 and 3 respectively. For examples of Linkage between Business Sectors and Complexity Categories Risks, see Tables QMS 1, EMS 2 and OH&SMS 2 by clicking on the MD5 file link below: | F31: IAF MD5 Issue 4 Version 3 (Rev Date: 14-Jun-2023)
B32: It is expected that business activities defined as low risk may require less audit time than the time calculated using Tables QMS 1, EMS 2 and OH&SMS 2 activities defined as medium risk will take the time calculated in the tables and activities defined as high risk will take more time; thus, audit days shall be decreased/increased accordingly by adding adequate Adjustment Factors.
B36: Audit Frequency
B38: Transfer / Takeover of Approval (ToA)
B40: Does this regard a ToA? | D40: At what stage is the client transferring?
B43: Change to Approval (CTA)
B45: Does this regard a CTA? | D45: What does this CTA cover?
E46: Describe what changes have been made to the client's certification, that affect upcoming audit visit's duration e.g. new site has been added, number of ENP has changed, addition of new process/production line changing Risk/Complexity level etc
B49: Sites Details
B50: Please enter Site details and delete all Sites and Standards that are not applicable. E.g. if you only have 1 site (Main/H.O.) for ISO 9001 only, enter by replacing existing information in the cell that contains "Site 01" and delete the info in the cells for the rest Sites 2 to 100 as well as the "Yes" entries under columns ISO 14001 and ISO 45001.
B52: Sites and Multi-Site Certification
B54: Is this a Multi-Site Certification? | D54: Is the Main Site excluded from Calculation? | F54: No
B55: Reduction % Due to Multi-Site: | C55: =IF('Client Info'!C54="Yes",20,0) -> 0 | D55: =IF(C55<>0,"%","")
B56: by selecting Yes, you indicate that this Certification satisfy the Eligibility criteria of MD 1 for a Multi-Site Certification
B58: If Yes, please name the Processes/ Sampling Names | C58: No Sampling Applicable | D58: Group/Activity A, e.g. Sales | E58: Group/Activity B, e.g. Production | F58: Group/Activity C, e.g. Storage | G58: Group/Activity D, e.g. Laboratories
B59: (create Samples manually for Sites with similar processes/activities)
D60: Standards Applicable | J60: Sampling Name
B61: Site Name/Description | C61: Address | D61: =IF(C26<>"Yes","",B26) | E61: =IF(C27<>"Yes","",B27) | F61: =IF(C28<>"Yes","",B28)
B63: All Sites | D63: {=IF(OR(D64:D164="Yes"),"Yes","")} | E63: {=IF(OR(E64:E164="Yes"),"Yes","")} | F63: {=IF(OR(F64:F164="Yes"),"Yes","")}
G64: Main Site/H.O. shall always be in the first row! | J64: Not included in Sampling - Main Site needs to be visited at least once annually
J65: No Sampling Applicable
...

Sheet Overview
B1: Overview
B2: Client Details
B3: Account Name: | C3: ='Client Info'!C20 -> 0 | I3: Created by: | K3: ='Client Info'!F16 -> 0
J4: (Team) Lead Auditor / Sales Opportunity Owner
B5: BOS Contract Number: | C5: ='Client Info'!F20 -> 0 | D5: Opportunity Name/link: | E5: ='Client Info'!F22 -> 0
B7: Product Summary
B9: Int Reduction: | C9: ='Integrated Reduction'!C29 | D9: % | E9: =IF('Client Info'!C54="Yes",CONCATENATE("Multi-Site Certification Reduction: -",'Client Info'!C55,"%"),"")
B10: =IF(OR(C13="Yes",C14="Yes",C15="Yes"),"↖","") | C10: =IF(OR(C13="Yes",C14="Yes",C15="Yes"),"Go to Integrated Reduction tab to select Level of Integration (click link on the left)","") | F10: Proposed Audit Days, per visit type / per product
B12: Product Name | C12: Is Product Integrated? (select Yes or No, as applicable) | D12: Complexity | F12: IA | G12: SV1 | H12: =IF('Client Info'!C36="6-monthly","SV2",IF(OR('Client Info'!C36="9-monthly",'Client Info'!C36="12-monthly"),"","")) | I12: =IF('Client Info'!C36="6-monthly","SV3",IF('Client Info'!C36="9-monthly","SV2","")) | J12: =IF('Client Info'!C36="6-monthly","SV4",IF(OR('Client Info'!C36="12-monthly",'Client Info'!C36="9-monthly"),"")) -> FALSE | K12: FV | L12: CR | M12: Remarks
B13: =IF('Client Info'!$C$26="Yes","ISO 9001","--") -> -- | D13: ='Client Info'!D26 -> 0 | F13: ='Manual Adjustments'!H8+'Manual Adjustments'!I8 -> 0 | G13: ='Manual Adjustments'!J8 -> #N/A | H13: ='Manual Adjustments'!K8 -> 0 | I13: ='Manual Adjustments'!L8 -> 0 | J13: ='Manual Adjustments'!M8 -> #N/A | K13: ='Manual Adjustments'!N8 -> #N/A | L13: ='Manual Adjustments'!O8 -> 0
B14: =IF('Client Info'!$C$27="Yes","ISO 14001","--") -> -- | D14: ='Client Info'!D27 -> 0 | F14: ='Manual Adjustments'!H10+'Manual Adjustments'!I10 -> 0 | G14: ='Manual Adjustments'!J10 -> #N/A | H14: ='Manual Adjustments'!K10 -> 0 | I14: ='Manual Adjustments'!L10 -> 0 | J14: ='Manual Adjustments'!M10 -> #N/A | K14: ='Manual Adjustments'!N10 -> #N/A | L14: ='Manual Adjustments'!O10 -> 0
B15: =IF('Client Info'!$C$28="Yes","ISO 45001","--") -> -- | D15: ='Client Info'!D28 -> 0 | F15: ='Manual Adjustments'!H12+'Manual Adjustments'!I12 -> 0 | G15: ='Manual Adjustments'!J12 -> #N/A | H15: ='Manual Adjustments'!K12 -> 0 | I15: ='Manual Adjustments'!L12 -> 0 | J15: ='Manual Adjustments'!M12 -> #N/A | K15: ='Manual Adjustments'!N12 -> #N/A | L15: ='Manual Adjustments'!O12 -> 0
B17: Total Number of Days (for all products combined) | F17: ='Manual Adjustments'!H15+'Manual Adjustments'!I15 -> 0 | G17: ='Manual Adjustments'!J15 -> #N/A | H17: ='Manual Adjustments'!K15 -> 0 | I17: ='Manual Adjustments'!L15 -> 0 | J17: ='Manual Adjustments'!M15 -> #N/A | K17: ='Manual Adjustments'!N15 -> #N/A | L17: ='Manual Adjustments'!O15 -> 0
B18: Does this regard a ToA? | C18: =IF('Client Info'!C40<>"Yes","No",'Client Info'!C40) -> No | D18: At what stage is the client transferring? | E18: ='Client Info'!E40 -> 0
B19: Does this regard a CTA? | C19: =IF('Client Info'!C45<>"Yes","No",'Client Info'!C45) -> No | D19: Reason for CTA | E19: ='Client Info'!E45 -> 0
B20: Calculate Audit Details
B22: Sites (if appicable): | C22: ENP | D22: Nominal Days | E22: Calculated Adjusted Days, per site / per product
D23: (for IA) | E23: IA | G23: SV1 | H23: =IF('Client Info'!C36="6-monthly","SV2",IF(OR('Client Info'!C36="9-monthly",'Client Info'!C36="12-monthly"),"","")) | I23: =IF('Client Info'!C36="6-monthly","SV3",IF('Client Info'!C36="9-monthly","SV2","")) | J23: =IF('Client Info'!C36="6-monthly","SV4",IF(OR('Client Info'!C36="12-monthly",'Client Info'!C36="9-monthly"),"")) -> FALSE | K23: FV | L23: CR
E24: Stage 1 | F24: Stage 2
B25: ='Client Info'!B64 -> 0
B26: ='Effective Employees'!B13 -> N/A | C26: ='Effective Employees'!F13 -> 0 | D26: ='Manual Adjustments'!G27 -> 0 | E26: =IF('Manual Adjustments'!H27<0.5,CEILING('Manual Adjustments'!H27,0.25),MROUND('Manual Adjustments'!H27,0.5)) -> 0 | F26: =IF('Manual Adjustments'!I27<0.5,CEILING('Manual Adjustments'!I27,0.25),MROUND('Manual Adjustments'!I27,0.25)) -> 0 | G26: =IF('Manual Adjustments'!J27<0.5,CEILING('Manual Adjustments'!J27,0.25),MROUND('Manual Adjustments'!J27,0.25)) -> #N/A | H26: =IF('Manual Adjustments'!K27<0.5,CEILING('Manual Adjustments'!K27,0.25),MROUND('Manual Adjustments'!K27,0.5)) -> 0 | I26: =IF('Manual Adjustments'!L27<0.5,CEILING('Manual Adjustments'!L27,0.25),MROUND('Manual Adjustments'!L27,0.25)) -> 0 | J26: =IF('Manual Adjustments'!M27<0.5,CEILING('Manual Adjustments'!M27,0.25),MROUND('Manual Adjustments'!M27,0.25)) -> #N/A | K26: =IF('Manual Adjustments'!N27<0.5,CEILING('Manual Adjustments'!N27,0.25),MROUND('Manual Adjustments'!N27,0.25)) -> #N/A | L26: =IF('Manual Adjustments'!O27<0.5,CEILING('Manual Adjustments'!O27,0.25),MROUND('Manual Adjustments'!O27,0.25)) -> 0
B27: ='Effective Employees'!B14 -> N/A | C27: ='Effective Employees'!F14 -> 0 | D27: ='Manual Adjustments'!G28 -> 0 | E27: =IF('Manual Adjustments'!H28<0.5,CEILING('Manual Adjustments'!H28,0.25),MROUND('Manual Adjustments'!H28,0.5)) -> 0 | F27: =IF('Manual Adjustments'!I28<0.5,CEILING('Manual Adjustments'!I28,0.25),MROUND('Manual Adjustments'!I28,0.25)) -> 0 | G27: =IF('Manual Adjustments'!J28<0.5,CEILING('Manual Adjustments'!J28,0.25),MROUND('Manual Adjustments'!J28,0.25)) -> #N/A | H27: =IF('Manual Adjustments'!K28<0.5,CEILING('Manual Adjustments'!K28,0.25),MROUND('Manual Adjustments'!K28,0.25)) -> 0 | I27: =IF('Manual Adjustments'!L28<0.5,CEILING('Manual Adjustments'!L28,0.25),MROUND('Manual Adjustments'!L28,0.25)) -> 0 | J27: =IF('Manual Adjustments'!M28<0.5,CEILING('Manual Adjustments'!M28,0.25),MROUND('Manual Adjustments'!M28,0.25)) -> #N/A | K27: =IF('Manual Adjustments'!N28<0.5,CEILING('Manual Adjustments'!N28,0.25),MROUND('Manual Adjustments'!N28,0.25)) -> #N/A | L27: =IF('Manual Adjustments'!O28<0.5,CEILING('Manual Adjustments'!O28,0.25),MROUND('Manual Adjustments'!O28,0.25)) -> 0
B28: ='Effective Employees'!B15 -> N/A | C28: ='Effective Employees'!F15 -> 0 | D28: ='Manual Adjustments'!G29 -> 0 | E28: =IF('Manual Adjustments'!H29<0.5,CEILING('Manual Adjustments'!H29,0.25),MROUND('Manual Adjustments'!H29,0.5)) -> 0 | F28: =IF('Manual Adjustments'!I29<0.5,CEILING('Manual Adjustments'!I29,0.25),MROUND('Manual Adjustments'!I29,0.25)) -> 0 | G28: =IF('Manual Adjustments'!J29<0.5,CEILING('Manual Adjustments'!J29,0.25),MROUND('Manual Adjustments'!J29,0.25)) -> #N/A | H28: =IF('Manual Adjustments'!K29<0.5,CEILING('Manual Adjustments'!K29,0.25),MROUND('Manual Adjustments'!K29,0.25)) -> 0 | I28: =IF('Manual Adjustments'!L29<0.5,CEILING('Manual Adjustments'!L29,0.25),MROUND('Manual Adjustments'!L29,0.25)) -> 0 | J28: =IF('Manual Adjustments'!M29<0.5,CEILING('Manual Adjustments'!M29,0.25),MROUND('Manual Adjustments'!M29,0.25)) -> #N/A | K28: =IF('Manual Adjustments'!N29<0.5,CEILING('Manual Adjustments'!N29,0.25),MROUND('Manual Adjustments'!N29,0.25)) -> #N/A | L28: =IF('Manual Adjustments'!O29<0.5,CEILING('Manual Adjustments'!O29,0.25),MROUND('Manual Adjustments'!O29,0.25)) -> 0
B29: ='Client Info'!B65 -> 0
B30: ='Effective Employees'!B16 -> N/A | C30: ='Effective Employees'!F16 -> 0 | D30: ='Manual Adjustments'!G30 -> 0 | E30: =IF('Manual Adjustments'!H30<0.25,CEILING('Manual Adjustments'!H30,0.25),MROUND('Manual Adjustments'!H30,0.25)) -> 0 | F30: =IF('Manual Adjustments'!I30<0.25,CEILING('Manual Adjustments'!I30,0.25),MROUND('Manual Adjustments'!I30,0.25)) -> 0 | G30: =IF('Manual Adjustments'!J30<0.25,CEILING('Manual Adjustments'!J30,0.25),MROUND('Manual Adjustments'!J30,0.25)) -> #N/A | H30: =IF('Manual Adjustments'!K30<0.25,CEILING('Manual Adjustments'!K30,0.25),MROUND('Manual Adjustments'!K30,0.25)) -> 0 | I30: =IF('Manual Adjustments'!L30<0.25,CEILING('Manual Adjustments'!L30,0.25),MROUND('Manual Adjustments'!L30,0.25)) -> 0 | J30: =IF('Manual Adjustments'!M30<0.25,CEILING('Manual Adjustments'!M30,0.25),MROUND('Manual Adjustments'!M30,0.25)) -> #N/A | K30: =IF('Manual Adjustments'!N30<0.25,CEILING('Manual Adjustments'!N30,0.25),MROUND('Manual Adjustments'!N30,0.25)) -> #N/A | L30: =IF('Manual Adjustments'!O30<0.25,CEILING('Manual Adjustments'!O30,0.25),MROUND('Manual Adjustments'!O30,0.25)) -> 0
B31: ='Effective Employees'!B17 -> N/A | C31: ='Effective Employees'!F17 -> 0 | D31: ='Manual Adjustments'!G31 -> 0 | E31: =IF('Manual Adjustments'!H31<0.25,CEILING('Manual Adjustments'!H31,0.25),MROUND('Manual Adjustments'!H31,0.25)) -> 0 | F31: =IF('Manual Adjustments'!I31<0.25,CEILING('Manual Adjustments'!I31,0.25),MROUND('Manual Adjustments'!I31,0.25)) -> 0 | G31: =IF('Manual Adjustments'!J31<0.25,CEILING('Manual Adjustments'!J31,0.25),MROUND('Manual Adjustments'!J31,0.25)) -> #N/A | H31: =IF('Manual Adjustments'!K31<0.25,CEILING('Manual Adjustments'!K31,0.25),MROUND('Manual Adjustments'!K31,0.25)) -> 0 | I31: =IF('Manual Adjustments'!L31<0.25,CEILING('Manual Adjustments'!L31,0.25),MROUND('Manual Adjustments'!L31,0.25)) -> 0 | J31: =IF('Manual Adjustments'!M31<0.25,CEILING('Manual Adjustments'!M31,0.25),MROUND('Manual Adjustments'!M31,0.25)) -> #N/A | K31: =IF('Manual Adjustments'!N31<0.25,CEILING('Manual Adjustments'!N31,0.25),MROUND('Manual Adjustments'!N31,0.25)) -> #N/A | L31: =IF('Manual Adjustments'!O31<0.25,CEILING('Manual Adjustments'!O31,0.25),MROUND('Manual Adjustments'!O31,0.25)) -> 0
B32: ='Effective Employees'!B18 -> N/A | C32: ='Effective Employees'!F18 -> 0 | D32: ='Manual Adjustments'!G32 -> 0 | E32: =IF('Manual Adjustments'!H32<0.25,CEILING('Manual Adjustments'!H32,0.25),MROUND('Manual Adjustments'!H32,0.25)) -> 0 | F32: =IF('Manual Adjustments'!I32<0.25,CEILING('Manual Adjustments'!I32,0.25),MROUND('Manual Adjustments'!I32,0.25)) -> 0 | G32: =IF('Manual Adjustments'!J32<0.25,CEILING('Manual Adjustments'!J32,0.25),MROUND('Manual Adjustments'!J32,0.25)) -> #N/A | H32: =IF('Manual Adjustments'!K32<0.25,CEILING('Manual Adjustments'!K32,0.25),MROUND('Manual Adjustments'!K32,0.25)) -> 0 | I32: =IF('Manual Adjustments'!L32<0.25,CEILING('Manual Adjustments'!L32,0.25),MROUND('Manual Adjustments'!L32,0.25)) -> 0 | J32: =IF('Manual Adjustments'!M32<0.25,CEILING('Manual Adjustments'!M32,0.25),MROUND('Manual Adjustments'!M32,0.25)) -> #N/A | K32: =IF('Manual Adjustments'!N32<0.25,CEILING('Manual Adjustments'!N32,0.25),MROUND('Manual Adjustments'!N32,0.25)) -> #N/A | L32: =IF('Manual Adjustments'!O32<0.25,CEILING('Manual Adjustments'!O32,0.25),MROUND('Manual Adjustments'!O32,0.25)) -> 0
B33: ='Client Info'!B66 -> 0
B34: ='Effective Employees'!B19 -> N/A | C34: ='Effective Employees'!F19 -> 0 | D34: ='Manual Adjustments'!G33 -> 0 | E34: =IF('Manual Adjustments'!H33<0.25,CEILING('Manual Adjustments'!H33,0.25),MROUND('Manual Adjustments'!H33,0.25)) -> 0 | F34: =IF('Manual Adjustments'!I33<0.25,CEILING('Manual Adjustments'!I33,0.25),MROUND('Manual Adjustments'!I33,0.25)) -> 0 | G34: =IF('Manual Adjustments'!J33<0.25,CEILING('Manual Adjustments'!J33,0.25),MROUND('Manual Adjustments'!J33,0.25)) -> #N/A | H34: =IF('Manual Adjustments'!K33<0.25,CEILING('Manual Adjustments'!K33,0.25),MROUND('Manual Adjustments'!K33,0.25)) -> 0 | I34: =IF('Manual Adjustments'!L33<0.25,CEILING('Manual Adjustments'!L33,0.25),MROUND('Manual Adjustments'!L33,0.25)) -> 0 | J34: =IF('Manual Adjustments'!M33<0.25,CEILING('Manual Adjustments'!M33,0.25),MROUND('Manual Adjustments'!M33,0.25)) -> #N/A | K34: =IF('Manual Adjustments'!N33<0.25,CEILING('Manual Adjustments'!N33,0.25),MROUND('Manual Adjustments'!N33,0.25)) -> #N/A | L34: =IF('Manual Adjustments'!O33<0.25,CEILING('Manual Adjustments'!O33,0.25),MROUND('Manual Adjustments'!O33,0.25)) -> 0
B35: ='Effective Employees'!B20 -> N/A | C35: ='Effective Employees'!F20 -> 0 | D35: ='Manual Adjustments'!G34 -> 0 | E35: =IF('Manual Adjustments'!H34<0.25,CEILING('Manual Adjustments'!H34,0.25),MROUND('Manual Adjustments'!H34,0.25)) -> 0 | F35: =IF('Manual Adjustments'!I34<0.25,CEILING('Manual Adjustments'!I34,0.25),MROUND('Manual Adjustments'!I34,0.25)) -> 0 | G35: =IF('Manual Adjustments'!J34<0.25,CEILING('Manual Adjustments'!J34,0.25),MROUND('Manual Adjustments'!J34,0.25)) -> #N/A | H35: =IF('Manual Adjustments'!K34<0.25,CEILING('Manual Adjustments'!K34,0.25),MROUND('Manual Adjustments'!K34,0.25)) -> 0 | I35: =IF('Manual Adjustments'!L34<0.25,CEILING('Manual Adjustments'!L34,0.25),MROUND('Manual Adjustments'!L34,0.25)) -> 0 | J35: =IF('Manual Adjustments'!M34<0.25,CEILING('Manual Adjustments'!M34,0.25),MROUND('Manual Adjustments'!M34,0.25)) -> #N/A | K35: =IF('Manual Adjustments'!N34<0.25,CEILING('Manual Adjustments'!N34,0.25),MROUND('Manual Adjustments'!N34,0.25)) -> #N/A | L35: =IF('Manual Adjustments'!O34<0.25,CEILING('Manual Adjustments'!O34,0.25),MROUND('Manual Adjustments'!O34,0.25)) -> 0
B36: ='Effective Employees'!B21 -> N/A | C36: ='Effective Employees'!F21 -> 0 | D36: ='Manual Adjustments'!G35 -> 0 | E36: =IF('Manual Adjustments'!H35<0.25,CEILING('Manual Adjustments'!H35,0.25),MROUND('Manual Adjustments'!H35,0.25)) -> 0 | F36: =IF('Manual Adjustments'!I35<0.25,CEILING('Manual Adjustments'!I35,0.25),MROUND('Manual Adjustments'!I35,0.25)) -> 0 | G36: =IF('Manual Adjustments'!J35<0.25,CEILING('Manual Adjustments'!J35,0.25),MROUND('Manual Adjustments'!J35,0.25)) -> #N/A | H36: =IF('Manual Adjustments'!K35<0.25,CEILING('Manual Adjustments'!K35,0.25),MROUND('Manual Adjustments'!K35,0.25)) -> 0 | I36: =IF('Manual Adjustments'!L35<0.25,CEILING('Manual Adjustments'!L35,0.25),MROUND('Manual Adjustments'!L35,0.25)) -> 0 | J36: =IF('Manual Adjustments'!M35<0.25,CEILING('Manual Adjustments'!M35,0.25),MROUND('Manual Adjustments'!M35,0.25)) -> #N/A | K36: =IF('Manual Adjustments'!N35<0.25,CEILING('Manual Adjustments'!N35,0.25),MROUND('Manual Adjustments'!N35,0.25)) -> #N/A | L36: =IF('Manual Adjustments'!O35<0.25,CEILING('Manual Adjustments'!O35,0.25),MROUND('Manual Adjustments'!O35,0.25)) -> 0
B37: ='Client Info'!B67 -> 0
B38: ='Effective Employees'!B22 -> N/A | C38: ='Effective Employees'!F22 -> 0 | D38: ='Manual Adjustments'!G36 -> 0 | E38: =IF('Manual Adjustments'!H36<0.25,CEILING('Manual Adjustments'!H36,0.25),MROUND('Manual Adjustments'!H36,0.25)) -> 0 | F38: =IF('Manual Adjustments'!I36<0.25,CEILING('Manual Adjustments'!I36,0.25),MROUND('Manual Adjustments'!I36,0.25)) -> 0 | G38: =IF('Manual Adjustments'!J36<0.25,CEILING('Manual Adjustments'!J36,0.25),MROUND('Manual Adjustments'!J36,0.25)) -> #N/A | H38: =IF('Manual Adjustments'!K36<0.25,CEILING('Manual Adjustments'!K36,0.25),MROUND('Manual Adjustments'!K36,0.25)) -> 0 | I38: =IF('Manual Adjustments'!L36<0.25,CEILING('Manual Adjustments'!L36,0.25),MROUND('Manual Adjustments'!L36,0.25)) -> 0 | J38: =IF('Manual Adjustments'!M36<0.25,CEILING('Manual Adjustments'!M36,0.25),MROUND('Manual Adjustments'!M36,0.25)) -> #N/A | K38: =IF('Manual Adjustments'!N36<0.25,CEILING('Manual Adjustments'!N36,0.25),MROUND('Manual Adjustments'!N36,0.25)) -> #N/A | L38: =IF('Manual Adjustments'!O36<0.25,CEILING('Manual Adjustments'!O36,0.25),MROUND('Manual Adjustments'!O36,0.25)) -> 0
B39: ='Effective Employees'!B23 -> N/A | C39: ='Effective Employees'!F23 -> 0 | D39: ='Manual Adjustments'!G37 -> 0 | E39: =IF('Manual Adjustments'!H37<0.25,CEILING('Manual Adjustments'!H37,0.25),MROUND('Manual Adjustments'!H37,0.25)) -> 0 | F39: =IF('Manual Adjustments'!I37<0.25,CEILING('Manual Adjustments'!I37,0.25),MROUND('Manual Adjustments'!I37,0.25)) -> 0 | G39: =IF('Manual Adjustments'!J37<0.25,CEILING('Manual Adjustments'!J37,0.25),MROUND('Manual Adjustments'!J37,0.25)) -> #N/A | H39: =IF('Manual Adjustments'!K37<0.25,CEILING('Manual Adjustments'!K37,0.25),MROUND('Manual Adjustments'!K37,0.25)) -> 0 | I39: =IF('Manual Adjustments'!L37<0.25,CEILING('Manual Adjustments'!L37,0.25),MROUND('Manual Adjustments'!L37,0.25)) -> 0 | J39: =IF('Manual Adjustments'!M37<0.25,CEILING('Manual Adjustments'!M37,0.25),MROUND('Manual Adjustments'!M37,0.25)) -> #N/A | K39: =IF('Manual Adjustments'!N37<0.25,CEILING('Manual Adjustments'!N37,0.25),MROUND('Manual Adjustments'!N37,0.25)) -> #N/A | L39: =IF('Manual Adjustments'!O37<0.25,CEILING('Manual Adjustments'!O37,0.25),MROUND('Manual Adjustments'!O37,0.25)) -> 0
B40: ='Effective Employees'!B24 -> N/A | C40: ='Effective Employees'!F24 -> 0 | D40: ='Manual Adjustments'!G38 -> 0 | E40: =IF('Manual Adjustments'!H38<0.25,CEILING('Manual Adjustments'!H38,0.25),MROUND('Manual Adjustments'!H38,0.25)) -> 0 | F40: =IF('Manual Adjustments'!I38<0.25,CEILING('Manual Adjustments'!I38,0.25),MROUND('Manual Adjustments'!I38,0.25)) -> 0 | G40: =IF('Manual Adjustments'!J38<0.25,CEILING('Manual Adjustments'!J38,0.25),MROUND('Manual Adjustments'!J38,0.25)) -> #N/A | H40: =IF('Manual Adjustments'!K38<0.25,CEILING('Manual Adjustments'!K38,0.25),MROUND('Manual Adjustments'!K38,0.25)) -> 0 | I40: =IF('Manual Adjustments'!L38<0.25,CEILING('Manual Adjustments'!L38,0.25),MROUND('Manual Adjustments'!L38,0.25)) -> 0 | J40: =IF('Manual Adjustments'!M38<0.25,CEILING('Manual Adjustments'!M38,0.25),MROUND('Manual Adjustments'!M38,0.25)) -> #N/A | K40: =IF('Manual Adjustments'!N38<0.25,CEILING('Manual Adjustments'!N38,0.25),MROUND('Manual Adjustments'!N38,0.25)) -> #N/A | L40: =IF('Manual Adjustments'!O38<0.25,CEILING('Manual Adjustments'!O38,0.25),MROUND('Manual Adjustments'!O38,0.25)) -> 0
B41: ='Client Info'!B68 -> 0
B42: ='Effective Employees'!B25 -> N/A | C42: ='Effective Employees'!F25 -> 0 | D42: ='Manual Adjustments'!G39 -> 0 | E42: =IF('Manual Adjustments'!H39<0.25,CEILING('Manual Adjustments'!H39,0.25),MROUND('Manual Adjustments'!H39,0.25)) -> 0 | F42: =IF('Manual Adjustments'!I39<0.25,CEILING('Manual Adjustments'!I39,0.25),MROUND('Manual Adjustments'!I39,0.25)) -> 0 | G42: =IF('Manual Adjustments'!J39<0.25,CEILING('Manual Adjustments'!J39,0.25),MROUND('Manual Adjustments'!J39,0.25)) -> #N/A | H42: =IF('Manual Adjustments'!K39<0.25,CEILING('Manual Adjustments'!K39,0.25),MROUND('Manual Adjustments'!K39,0.25)) -> 0 | I42: =IF('Manual Adjustments'!L39<0.25,CEILING('Manual Adjustments'!L39,0.25),MROUND('Manual Adjustments'!L39,0.25)) -> 0 | J42: =IF('Manual Adjustments'!M39<0.25,CEILING('Manual Adjustments'!M39,0.25),MROUND('Manual Adjustments'!M39,0.25)) -> #N/A | K42: =IF('Manual Adjustments'!N39<0.25,CEILING('Manual Adjustments'!N39,0.25),MROUND('Manual Adjustments'!N39,0.25)) -> #N/A | L42: =IF('Manual Adjustments'!O39<0.25,CEILING('Manual Adjustments'!O39,0.25),MROUND('Manual Adjustments'!O39,0.25)) -> 0
B43: ='Effective Employees'!B26 -> N/A | C43: ='Effective Employees'!F26 -> 0 | D43: ='Manual Adjustments'!G40 -> 0 | E43: =IF('Manual Adjustments'!H40<0.25,CEILING('Manual Adjustments'!H40,0.25),MROUND('Manual Adjustments'!H40,0.25)) -> 0 | F43: =IF('Manual Adjustments'!I40<0.25,CEILING('Manual Adjustments'!I40,0.25),MROUND('Manual Adjustments'!I40,0.25)) -> 0 | G43: =IF('Manual Adjustments'!J40<0.25,CEILING('Manual Adjustments'!J40,0.25),MROUND('Manual Adjustments'!J40,0.25)) -> #N/A | H43: =IF('Manual Adjustments'!K40<0.25,CEILING('Manual Adjustments'!K40,0.25),MROUND('Manual Adjustments'!K40,0.25)) -> 0 | I43: =IF('Manual Adjustments'!L40<0.25,CEILING('Manual Adjustments'!L40,0.25),MROUND('Manual Adjustments'!L40,0.25)) -> 0 | J43: =IF('Manual Adjustments'!M40<0.25,CEILING('Manual Adjustments'!M40,0.25),MROUND('Manual Adjustments'!M40,0.25)) -> #N/A | K43: =IF('Manual Adjustments'!N40<0.25,CEILING('Manual Adjustments'!N40,0.25),MROUND('Manual Adjustments'!N40,0.25)) -> #N/A | L43: =IF('Manual Adjustments'!O40<0.25,CEILING('Manual Adjustments'!O40,0.25),MROUND('Manual Adjustments'!O40,0.25)) -> 0
B44: ='Effective Employees'!B27 -> N/A | C44: ='Effective Employees'!F27 -> 0 | D44: ='Manual Adjustments'!G41 -> 0 | E44: =IF('Manual Adjustments'!H41<0.25,CEILING('Manual Adjustments'!H41,0.25),MROUND('Manual Adjustments'!H41,0.25)) -> 0 | F44: =IF('Manual Adjustments'!I41<0.25,CEILING('Manual Adjustments'!I41,0.25),MROUND('Manual Adjustments'!I41,0.25)) -> 0 | G44: =IF('Manual Adjustments'!J41<0.25,CEILING('Manual Adjustments'!J41,0.25),MROUND('Manual Adjustments'!J41,0.25)) -> #N/A | H44: =IF('Manual Adjustments'!K41<0.25,CEILING('Manual Adjustments'!K41,0.25),MROUND('Manual Adjustments'!K41,0.25)) -> 0 | I44: =IF('Manual Adjustments'!L41<0.25,CEILING('Manual Adjustments'!L41,0.25),MROUND('Manual Adjustments'!L41,0.25)) -> 0 | J44: =IF('Manual Adjustments'!M41<0.25,CEILING('Manual Adjustments'!M41,0.25),MROUND('Manual Adjustments'!M41,0.25)) -> #N/A | K44: =IF('Manual Adjustments'!N41<0.25,CEILING('Manual Adjustments'!N41,0.25),MROUND('Manual Adjustments'!N41,0.25)) -> #N/A | L44: =IF('Manual Adjustments'!O41<0.25,CEILING('Manual Adjustments'!O41,0.25),MROUND('Manual Adjustments'!O41,0.25)) -> 0
B45: ='Client Info'!B69 -> 0
...

Sheet Integrated Reduction
B1: Integrated Reduction
B2: Audit Reduction for Integrated Products
B4: Integrated Products: | C4: =IF(Overview!C13="Yes",Overview!B13,"") | D4: =IF(Overview!C14="Yes",Overview!B14,"") | E4: =IF(Overview!C15="Yes",Overview!B15,"") | H4: Return to Overview
B7: Characterisations that have been Considered for Reduction (as per MD 11, Annex 1):
B8: An integrated documentation set, including work instructions to a good level of development, as appropriate | E8: Yes | F8: Based on what is applicable, the Level of Integration will need to be adjusted accordingly. For more information see 'Level of Integration Percentage Remarks' below
B9: Management Reviews that consider the overall business strategy and plan | E9: Yes
B10: An integrated approach to internal audits | E10: Yes
B11: An integrated approach to policy and objectives | E11: Yes
B12: An integrated approach to systems processes | E12: Yes
B13: An integrated approach to improvement mechanisms (corrective and preventive action, measurement and continual improvement) | E13: Yes
B14: Integrated management support and responsibilities | E14: Yes
B16: Reduction Percent Calculation
B18: Level of Integration Percentage: | C18: =IF(OR(Overview!C13="Yes",Overview!C14="Yes",Overview!C14="Yes"),COUNTIF(E8:E14,"Yes")/7*100,"")
B20: Level of Integration Percentage Remarks: | C20: =IF((AND(C18<=100,C18>80)),B46,(IF((AND(C18<80,C18>60)),B47,(IF((AND(C18<60,C18>40)),B48,(IF((AND(C18<40,C18>20)),B49,B50))))))) -> The Management Systems are not integrated
B24: Team's Ability to Perform Integrated Audit: | C24: 100 | G24: Note:
B26: Ability to Perform Integrated Audit Remarks: | C26: =IF(C24=100,M46,IF(OR(C24=80,C24=60,C24=40),M47,M48)) -> Each team member is qualified for all products | G26: In most cases the Audit team cannot be defined beforehand; therefore users should select 80% or, in case they know that the audit team can perform an integrated audit, to select 100%
G28: It is strongly advised not to use a reduction percent greater than 10% so as not to complicate the planning process.
B29: Reduction Percent: | C29: =IF(C18="","",IF(AND(C18<>"",C24=""),"Select applicable % for both fields",-(IF(AND(C18<=100,C18>80,C24=100),20,IF(AND(C18<=100,C18>80,C24=80),15,IF(AND(C18<=80,C18>60,C24=100),15,IF(AND(C18<=80,C18>60,C24=80),15,IF(AND(C18<=100,C18>80,C24=60),10,IF(AND(C18<=80,C18>60,C24=60),10,IF(AND(C18<=60,C18>40,C24=60),10,IF(AND(C18<=60,C18>40,C24=80),10,IF(AND(C18<=60,C18>40,C24=100),10,IF(AND(C18<=100,C18>80,C24=40),5,IF(AND(C18<=80,C18>60,C24=40),5,IF(AND(C18<=60,C18>40,C24=40),5,IF(AND(C18<=40,C18>20,C24=40),5,IF(AND(C18<=40,C18>20,C24=60),5,IF(AND(C18<=40,C18>20,C24=80),5,IF(AND(C18<=40,C18>20,C24=100),5,IF(OR(C18<=20,C24="from 0 to 20"),0,N42)))))))))))))))))))) | E29: %
A35: Hidden Cells
A37: Level of Integration Percentage | C37: Integration Factor / Reduction | M37: Ability to Perform Integrated Audit | R37: Characterisations have been Considered for Reduction
A38: 100 | B38: Full | C38: 0.8 | M38: 100 | R38: Yes
A39: 80 | B39: Medium | C39: 0.85 | M39: 80 | R39: No
A40: 60 | B40: Low | C40: 0.9 | M40: 60
A41: 40 | B41: Limited | C41: 0.95 | M41: 40
A42: from 0 to 20 | B42: No integration | C42: 1 | M42: from 0 to 20 | N42: No integration
M43: 0
B45: Level of Integration Percentage Remarks: | M45: Ability to Perform Integrated Audit Remarks:
B46: The management systems are fully integrated (Top management procedures and processes, such as Policy, Manual or Management Review, at least 80% of the Management Procedures and Processes such as Document Control, Records, Internal Audits, Corrective Actions, Risk Analysis, etc, plus at least 80% of the Operational Processes and procedures such as Production Control, Purchasing, Monitoring (e.g.: Procedure for operational control also covers Environmental and Health & Safety aspects related to the activity) etc are integrated) | M46: Each team member is qualified for all products
B47: The management systems have a medium level of integration (Top management procedures and processes, such as Policy, Manual or Management Review plus at least 80% of the Management Procedures and Processes such as Document Control, Records, Internal Audits, Corrective Actions, Risk Analysis, etc, are integrated) | M47: The audit team is partially qualified for the applicable products
B48: The management systems have a low level of integration (Top management procedures and processes, such as Policy, Manual or Management Review plus at least 50% of the Management Procedures and Processes such as Document Control, Records, Internal Audits, Corrective Actions, Risk Analysis, etc, are integrated) | M48: The audit team cannot conduct combined audits for Standards
B49: The management systems have a limited level of integration (Only top management procedures and processes, such as Policy, Manual or Management Review are integrated)
B50: The Management Systems are not integrated
A52: Reduction Percent
A53: 20
A54: 15
A55: 10
A56: 5
A57: 0

Sheet Effective Employees
B1: Effective Number of Personnel (ENP) / Effective Employees
B2: Product Name: | C2: =IF('Client Info'!$C$26="Yes","ISO 9001","--") -> -- | D2: =IF('Client Info'!$C$27="Yes","ISO 14001","--") -> -- | E2: =IF('Client Info'!$C$28="Yes","ISO 45001","--") -> --
B3: See MD1, MD5 and MD22 for definitions etc.; for further information on determining ENP pls see | H3: Quotation Guidance | I3: Effective Employees - Guidance
B5: Product Name | C5: Site | D5: Total Head Count (client input) | E5: Total No of FTE * enter the total number of employees | F5: Total Effective No of Emp (Effective Number of Personnel - ENP) * including contractors personnel working on the site, where applicable (see Notes on the right) | G5: Reduction Percentage | H5: Remarks | I5: Consider also the below:
H6: For your easy reference, select from/copy the below (ref. MD5/Clause 2.3): | I6: - Personnel working on shifts
H7: No Staff Reduction | I7: - Administrative and all categories of office staff
H8: Part time personnel and/or employees partially in scope | I8: - Employment of large numbers of unskilled personnel
H9: Similar or repetitive process within scope | I9: - Low Complexity/Risk Activities
H10: Shift work employees | I10: - Seasonal operations
H11: Temporary unskilled personnel | I11: → calculate based on the personnel typically present in
I12: peak season operations
B13: =IF('Client Info'!$D$64="Yes",'Client Info'!$D$61,"N/A") -> N/A | C13: =IF('Client Info'!F54="Yes","Main site excluded from Calculation",IF(B13="ISO 9001",'Client Info'!$B$64,"N/A")) -> N/A | I13: {=IFERROR(_xlfn.IFS(AND(B13<>"",B13<>"N/A",D13=""),"Please enter Total Head Count, since it cannot be left blank",AND(B13<>"",B13<>"N/A",F13=""),"Please enter ENP, since it cannot be left blank"),"")}
B14: =IF('Client Info'!$E$64="Yes",'Client Info'!$E$61,"N/A") -> N/A | C14: =IF('Client Info'!F54="Yes","Main site excluded from Calculation",IF(B14="ISO 14001",'Client Info'!$B$64,"N/A")) -> N/A | I14: {=IFERROR(_xlfn.IFS(AND(B14<>"",B14<>"N/A",D14=""),"Please enter Total Head Count , since it cannot be left blank",AND(B14<>"",B14<>"N/A",F14=""),"Please enter ENP, since it cannot be left blank"),"")}
B15: =IF('Client Info'!$F$64="Yes",'Client Info'!$F$61,"N/A") -> N/A | C15: =IF('Client Info'!F54="Yes","Main site excluded from Calculation",IF(B15="ISO 45001",'Client Info'!$B$64,"N/A")) -> N/A | I15: {=IFERROR(_xlfn.IFS(AND(B15<>"",B15<>"N/A",D15=""),"Please enter Total Head Count, since it cannot be left blank",AND(B15<>"",B15<>"N/A",F15=""),"Please enter ENP, since it cannot be left blank"),"")}
B16: =IF('Client Info'!$D$65="Yes",'Client Info'!$D$61,"N/A") -> N/A | C16: =IF(B16="ISO 9001",'Client Info'!$B$65,"N/A") -> N/A | G16: =IF(C16="N/A","",IFERROR(((D16-F16)/D16),0)) | I16: {=IFERROR(_xlfn.IFS(AND(B16<>"",B16<>"N/A",D16=""),"Please enter Total Head Count, since it cannot be left blank",AND(B16<>"",B16<>"N/A",F16=""),"Please enter ENP, since it cannot be left blank"),"")}
B17: =IF('Client Info'!$E$65="Yes",'Client Info'!$E$61,"N/A") -> N/A | C17: =IF(B17="ISO 14001",'Client Info'!$B$65,"N/A") -> N/A | G17: =IF(C17="N/A","",IFERROR(((D17-F17)/D17),0)) | I17: {=IFERROR(_xlfn.IFS(AND(B17<>"",B17<>"N/A",D17=""),"Please enter Total Head Count , since it cannot be left blank",AND(B17<>"",B17<>"N/A",F17=""),"Please enter ENP, since it cannot be left blank"),"")}
B18: =IF('Client Info'!$F$65="Yes",'Client Info'!$F$61,"N/A") -> N/A | C18: =IF(B18="ISO 45001",'Client Info'!$B$65,"N/A") -> N/A | G18: =IF(C18="N/A","",IFERROR(((D18-F18)/D18),0)) | I18: {=IFERROR(_xlfn.IFS(AND(B18<>"",B18<>"N/A",D18=""),"Please enter Total Head Count, since it cannot be left blank",AND(B18<>"",B18<>"N/A",F18=""),"Please enter ENP, since it cannot be left blank"),"")}
B19: =IF('Client Info'!$D$66="Yes",'Client Info'!$D$61,"N/A") -> N/A | C19: =IF(B19="ISO 9001",'Client Info'!$B$66,"N/A") -> N/A | G19: =IF(C19="N/A","",IFERROR(((D19-F19)/D19),0)) | I19: {=IFERROR(_xlfn.IFS(AND(B19<>"",B19<>"N/A",D19=""),"Please enter Total Head Count, since it cannot be left blank",AND(B19<>"",B19<>"N/A",F19=""),"Please enter ENP, since it cannot be left blank"),"")}
B20: =IF('Client Info'!$E$66="Yes",'Client Info'!$E$61,"N/A") -> N/A | C20: =IF(B20="ISO 14001",'Client Info'!$B$66,"N/A") -> N/A | G20: =IF(C20="N/A","",IFERROR(((D20-F20)/D20),0)) | I20: {=IFERROR(_xlfn.IFS(AND(B20<>"",B20<>"N/A",D20=""),"Please enter Total Head Count , since it cannot be left blank",AND(B20<>"",B20<>"N/A",F20=""),"Please enter ENP, since it cannot be left blank"),"")}
B21: =IF('Client Info'!$F$66="Yes",'Client Info'!$F$61,"N/A") -> N/A | C21: =IF(B21="ISO 45001",'Client Info'!$B$66,"N/A") -> N/A | G21: =IF(C21="N/A","",IFERROR(((D21-F21)/D21),0)) | I21: {=IFERROR(_xlfn.IFS(AND(B21<>"",B21<>"N/A",D21=""),"Please enter Total Head Count, since it cannot be left blank",AND(B21<>"",B21<>"N/A",F21=""),"Please enter ENP, since it cannot be left blank"),"")}
B22: =IF('Client Info'!$D$67="Yes",'Client Info'!$D$61,"N/A") -> N/A | C22: =IF(B22="ISO 9001",'Client Info'!$B$67,"N/A") -> N/A | G22: =IF(C22="N/A","",IFERROR(((D22-F22)/D22),0)) | I22: {=IFERROR(_xlfn.IFS(AND(B22<>"",B22<>"N/A",D22=""),"Please enter Total Head Count, since it cannot be left blank",AND(B22<>"",B22<>"N/A",F22=""),"Please enter ENP, since it cannot be left blank"),"")}
B23: =IF('Client Info'!$E$67="Yes",'Client Info'!$E$61,"N/A") -> N/A | C23: =IF(B23="ISO 14001",'Client Info'!$B$67,"N/A") -> N/A | G23: =IF(C23="N/A","",IFERROR(((D23-F23)/D23),0)) | I23: {=IFERROR(_xlfn.IFS(AND(B23<>"",B23<>"N/A",D23=""),"Please enter Total Head Count , since it cannot be left blank",AND(B23<>"",B23<>"N/A",F23=""),"Please enter ENP, since it cannot be left blank"),"")}
B24: =IF('Client Info'!$F$67="Yes",'Client Info'!$F$61,"N/A") -> N/A | C24: =IF(B24="ISO 45001",'Client Info'!$B$67,"N/A") -> N/A | G24: =IF(C24="N/A","",IFERROR(((D24-F24)/D24),0)) | I24: {=IFERROR(_xlfn.IFS(AND(B24<>"",B24<>"N/A",D24=""),"Please enter Total Head Count, since it cannot be left blank",AND(B24<>"",B24<>"N/A",F24=""),"Please enter ENP, since it cannot be left blank"),"")}
B25: =IF('Client Info'!$D$68="Yes",'Client Info'!$D$61,"N/A") -> N/A | C25: =IF(B25="ISO 9001",'Client Info'!$B$68,"N/A") -> N/A | G25: =IF(C25="N/A","",IFERROR(((D25-F25)/D25),0)) | I25: {=IFERROR(_xlfn.IFS(AND(B25<>"",B25<>"N/A",D25=""),"Please enter Total Head Count, since it cannot be left blank",AND(B25<>"",B25<>"N/A",F25=""),"Please enter ENP, since it cannot be left blank"),"")}
B26: =IF('Client Info'!$E$68="Yes",'Client Info'!$E$61,"N/A") -> N/A | C26: =IF(B26="ISO 14001",'Client Info'!$B$68,"N/A") -> N/A | G26: =IF(C26="N/A","",IFERROR(((D26-F26)/D26),0)) | I26: {=IFERROR(_xlfn.IFS(AND(B26<>"",B26<>"N/A",D26=""),"Please enter Total Head Count , since it cannot be left blank",AND(B26<>"",B26<>"N/A",F26=""),"Please enter ENP, since it cannot be left blank"),"")}
B27: =IF('Client Info'!$F$68="Yes",'Client Info'!$F$61,"N/A") -> N/A | C27: =IF(B27="ISO 45001",'Client Info'!$B$68,"N/A") -> N/A | G27: =IF(C27="N/A","",IFERROR(((D27-F27)/D27),0)) | I27: {=IFERROR(_xlfn.IFS(AND(B27<>"",B27<>"N/A",D27=""),"Please enter Total Head Count, since it cannot be left blank",AND(B27<>"",B27<>"N/A",F27=""),"Please enter ENP, since it cannot be left blank"),"")}
B28: =IF('Client Info'!$D$69="Yes",'Client Info'!$D$61,"N/A") -> N/A | C28: =IF(B28="ISO 9001",'Client Info'!$B$69,"N/A") -> N/A | G28: =IF(C28="N/A","",IFERROR(((D28-F28)/D28),0)) | I28: {=IFERROR(_xlfn.IFS(AND(B28<>"",B28<>"N/A",D28=""),"Please enter Total Head Count, since it cannot be left blank",AND(B28<>"",B28<>"N/A",F28=""),"Please enter ENP, since it cannot be left blank"),"")}
B29: =IF('Client Info'!$E$69="Yes",'Client Info'!$E$61,"N/A") -> N/A | C29: =IF(B29="ISO 14001",'Client Info'!$B$69,"N/A") -> N/A | G29: =IF(C29="N/A","",IFERROR(((D29-F29)/D29),0)) | I29: {=IFERROR(_xlfn.IFS(AND(B29<>"",B29<>"N/A",D29=""),"Please enter Total Head Count , since it cannot be left blank",AND(B29<>"",B29<>"N/A",F29=""),"Please enter ENP, since it cannot be left blank"),"")}
B30: =IF('Client Info'!$F$69="Yes",'Client Info'!$F$61,"N/A") -> N/A | C30: =IF(B30="ISO 45001",'Client Info'!$B$69,"N/A") -> N/A | G30: =IF(C30="N/A","",IFERROR(((D30-F30)/D30),0)) | I30: {=IFERROR(_xlfn.IFS(AND(B30<>"",B30<>"N/A",D30=""),"Please enter Total Head Count, since it cannot be left blank",AND(B30<>"",B30<>"N/A",F30=""),"Please enter ENP, since it cannot be left blank"),"")}
B31: =IF('Client Info'!$D$70="Yes",'Client Info'!$D$61,"N/A") -> N/A | C31: =IF(B31="ISO 9001",'Client Info'!$B$70,"N/A") -> N/A | G31: =IF(C31="N/A","",IFERROR(((D31-F31)/D31),0)) | I31: {=IFERROR(_xlfn.IFS(AND(B31<>"",B31<>"N/A",D31=""),"Please enter Total Head Count, since it cannot be left blank",AND(B31<>"",B31<>"N/A",F31=""),"Please enter ENP, since it cannot be left blank"),"")}
B32: =IF('Client Info'!$E$70="Yes",'Client Info'!$E$61,"N/A") -> N/A | C32: =IF(B32="ISO 14001",'Client Info'!$B$70,"N/A") -> N/A | G32: =IF(C32="N/A","",IFERROR(((D32-F32)/D32),0)) | I32: {=IFERROR(_xlfn.IFS(AND(B32<>"",B32<>"N/A",D32=""),"Please enter Total Head Count , since it cannot be left blank",AND(B32<>"",B32<>"N/A",F32=""),"Please enter ENP, since it cannot be left blank"),"")}
B33: =IF('Client Info'!$F$70="Yes",'Client Info'!$F$61,"N/A") -> N/A | C33: =IF(B33="ISO 45001",'Client Info'!$B$70,"N/A") -> N/A | I33: {=IFERROR(_xlfn.IFS(AND(B33<>"",B33<>"N/A",D33=""),"Please enter Total Head Count, since it cannot be left blank",AND(B33<>"",B33<>"N/A",F33=""),"Please enter ENP, since it cannot be left blank"),"")}
B34: =IF('Client Info'!$D$71="Yes",'Client Info'!$D$61,"N/A") -> N/A | C34: =IF(B34="ISO 9001",'Client Info'!$B$71,"N/A") -> N/A | I34: {=IFERROR(_xlfn.IFS(AND(B34<>"",B34<>"N/A",D34=""),"Please enter Total Head Count, since it cannot be left blank",AND(B34<>"",B34<>"N/A",F34=""),"Please enter ENP, since it cannot be left blank"),"")}
B35: =IF('Client Info'!$E$71="Yes",'Client Info'!$E$61,"N/A") -> N/A | C35: =IF(B35="ISO 14001",'Client Info'!$B$71,"N/A") -> N/A | I35: {=IFERROR(_xlfn.IFS(AND(B35<>"",B35<>"N/A",D35=""),"Please enter Total Head Count , since it cannot be left blank",AND(B35<>"",B35<>"N/A",F35=""),"Please enter ENP, since it cannot be left blank"),"")}
B36: =IF('Client Info'!$F$71="Yes",'Client Info'!$F$61,"N/A") -> N/A | C36: =IF(B36="ISO 45001",'Client Info'!$B$71,"N/A") -> N/A | I36: {=IFERROR(_xlfn.IFS(AND(B36<>"",B36<>"N/A",D36=""),"Please enter Total Head Count, since it cannot be left blank",AND(B36<>"",B36<>"N/A",F36=""),"Please enter ENP, since it cannot be left blank"),"")}
B37: =IF('Client Info'!$D$72="Yes",'Client Info'!$D$61,"N/A") -> N/A | C37: =IF(B37="ISO 9001",'Client Info'!$B$72,"N/A") -> N/A | I37: {=IFERROR(_xlfn.IFS(AND(B37<>"",B37<>"N/A",D37=""),"Please enter Total Head Count, since it cannot be left blank",AND(B37<>"",B37<>"N/A",F37=""),"Please enter ENP, since it cannot be left blank"),"")}
B38: =IF('Client Info'!$E$72="Yes",'Client Info'!$E$61,"N/A") -> N/A | C38: =IF(B38="ISO 14001",'Client Info'!$B$72,"N/A") -> N/A | I38: {=IFERROR(_xlfn.IFS(AND(B38<>"",B38<>"N/A",D38=""),"Please enter Total Head Count , since it cannot be left blank",AND(B38<>"",B38<>"N/A",F38=""),"Please enter ENP, since it cannot be left blank"),"")}
B39: =IF('Client Info'!$F$72="Yes",'Client Info'!$F$61,"N/A") -> N/A | C39: =IF(B39="ISO 45001",'Client Info'!$B$72,"N/A") -> N/A | I39: {=IFERROR(_xlfn.IFS(AND(B39<>"",B39<>"N/A",D39=""),"Please enter Total Head Count, since it cannot be left blank",AND(B39<>"",B39<>"N/A",F39=""),"Please enter ENP, since it cannot be left blank"),"")}
B40: =IF('Client Info'!$D$73="Yes",'Client Info'!$D$61,"N/A") -> N/A | C40: =IF(B40="ISO 9001",'Client Info'!$B$73,"N/A") -> N/A | I40: {=IFERROR(_xlfn.IFS(AND(B40<>"",B40<>"N/A",D40=""),"Please enter Total Head Count, since it cannot be left blank",AND(B40<>"",B40<>"N/A",F40=""),"Please enter ENP, since it cannot be left blank"),"")}
B41: =IF('Client Info'!$E$73="Yes",'Client Info'!$E$61,"N/A") -> N/A | C41: =IF(B41="ISO 14001",'Client Info'!$B$73,"N/A") -> N/A | I41: {=IFERROR(_xlfn.IFS(AND(B41<>"",B41<>"N/A",D41=""),"Please enter Total Head Count , since it cannot be left blank",AND(B41<>"",B41<>"N/A",F41=""),"Please enter ENP, since it cannot be left blank"),"")}
...

Sheet Adjustment Factors
B1: Adjustment Factors
B2: Product Name: | E2: =IF('Client Info'!$C$26="Yes","ISO 9001","--") -> -- | G2: =IF('Client Info'!$C$27="Yes","ISO 14001","--") -> -- | H2: =IF('Client Info'!$C$28="Yes","ISO 45001","--") -> --
B3: See MD1, MD5 and MD22 for definitions etc.; for further information on determining ENP pls see | G3: Quotation Guidance
B5: Effective Employee Count
B6: Product Name | C6: Site | D6: Adjustment Factor | E6: Variance | F6: +/- | G6: Var % | H6: Total Reduction per Site for each Standard | L6: Remarks
H7: ISO 9001 | I7: ISO 14001 | J7: ISO 45001 | P7: ISO 9001 | Q7: ISO 14001 | R7: ISO 45001
E8: {=_xlfn.IFS(LEFT(D8,3)="[D]","Decrease",LEFT(D8,3)="[I]","Increase",D8="","")} | F8: {=IFERROR(_xlfn.IFS(E8="Decrease",-1*G8,E8="Increase",G8),0)} -> 0 | G8: =IF(E8<>"",10%,0) -> 0 | H8: =IF($H$7=B8,VLOOKUP(C8,$Z$511:$AA$612,2,FALSE),0) -> 0 | I8: =IF($I$7=B8,VLOOKUP(C8,$AO$511:$AP$612,2,FALSE),0) -> 0 | J8: =IF($J$7=B8,VLOOKUP(C8,$BB$511:$BC$612,2,FALSE),0) -> 0 | K8: {=IFERROR(_xlfn.IFS(B8&"|"&C8&"|"&D8&"|"&"Duplicate"=P8,"This factor has already been used. Please revise.",B8&"|"&C8&"|"&D8&"|"&"Duplicate"=Q8,"This factor has already been used. Please revise.",B8&"|"&C8&"|"&D8&"|"&"Duplicate"=R8,"This factor has already been used. Please revise.",(H8<-0.3),"Please check reduction percentage since no more than -30% total reduction can be applied",(I8<-0.3),"Please check reduction percentage since no more than -30% total reduction can be applied",(J8<-0.3),"Please check reduction percentage since no more than -30% total reduction can be applied",AND(D8="[D] Client is not design responsible or other standard elements in the scope",G8>15%),"If Design is not included in the scope a maximum 15% reduction can be applied; please revise."),"")} | P8: =IFERROR(VLOOKUP(B8&"|"&C8&"|"&D8&"|"&"Duplicate",$AI$408:$AJ$508,1,FALSE),"") | Q8: =IFERROR(VLOOKUP(B8&"|"&C8&"|"&D8&"|"&"Duplicate",$AX$408:$AY$508,1,FALSE),"") | R8: =IFERROR(VLOOKUP(B8&"|"&C8&"|"&D8&"|"&"Duplicate",$BV$408:$BW$508,1,FALSE),"")
E9: {=_xlfn.IFS(LEFT(D9,3)="[D]","Decrease",LEFT(D9,3)="[I]","Increase",D9="","")} | F9: {=IFERROR(_xlfn.IFS(E9="Decrease",-1*G9,E9="Increase",G9),0)} -> 0 | G9: =IF(E9<>"",10%,0) -> 0 | H9: =IF($H$7=B9,VLOOKUP(C9,$Z$511:$AA$612,2,FALSE),0) -> 0 | I9: =IF($I$7=B9,VLOOKUP(C9,$AO$511:$AP$612,2,FALSE),0) -> 0 | J9: =IF($J$7=B9,VLOOKUP(C9,$BB$511:$BC$612,2,FALSE),0) -> 0 | K9: {=IFERROR(_xlfn.IFS(B9&"|"&C9&"|"&D9&"|"&"Duplicate"=P9,"This factor has already been used. Please revise.",B9&"|"&C9&"|"&D9&"|"&"Duplicate"=Q9,"This factor has already been used. Please revise.",B9&"|"&C9&"|"&D9&"|"&"Duplicate"=R9,"This factor has already been used. Please revise.",(H9<-0.3),"Please check reduction percentage since no more than -30% total reduction can be applied",(I9<-0.3),"Please check reduction percentage since no more than -30% total reduction can be applied",(J9<-0.3),"Please check reduction percentage since no more than -30% total reduction can be applied",AND(D9="[D] Client is not design responsible or other standard elements in the scope",G9>15%),"If Design is not included in the scope a maximum 15% reduction can be applied; please revise."),"")} | P9: =IFERROR(VLOOKUP(B9&"|"&C9&"|"&D9&"|"&"Duplicate",$AI$408:$AJ$508,1,FALSE),"") | Q9: =IFERROR(VLOOKUP(B9&"|"&C9&"|"&D9&"|"&"Duplicate",$AX$408:$AY$508,1,FALSE),"") | R9: =IFERROR(VLOOKUP(B9&"|"&C9&"|"&D9&"|"&"Duplicate",$BV$408:$BW$508,1,FALSE),"")
E10: {=_xlfn.IFS(LEFT(D10,3)="[D]","Decrease",LEFT(D10,3)="[I]","Increase",D10="","")} | F10: {=IFERROR(_xlfn.IFS(E10="Decrease",-1*G10,E10="Increase",G10),0)} -> 0 | G10: =IF(E10<>"",10%,0) -> 0 | H10: =IF($H$7=B10,VLOOKUP(C10,$Z$511:$AA$612,2,FALSE),0) -> 0 | I10: =IF($I$7=B10,VLOOKUP(C10,$AO$511:$AP$612,2,FALSE),0) -> 0 | J10: =IF($J$7=B10,VLOOKUP(C10,$BB$511:$BC$612,2,FALSE),0) -> 0 | K10: {=IFERROR(_xlfn.IFS(B10&"|"&C10&"|"&D10&"|"&"Duplicate"=P10,"This factor has already been used. Please revise.",B10&"|"&C10&"|"&D10&"|"&"Duplicate"=Q10,"This factor has already been used. Please revise.",B10&"|"&C10&"|"&D10&"|"&"Duplicate"=R10,"This factor has already been used. Please revise.",(H10<-0.3),"Please check reduction percentage since no more than -30% total reduction can be applied",(I10<-0.3),"Please check reduction percentage since no more than -30% total reduction can be applied",(J10<-0.3),"Please check reduction percentage since no more than -30% total reduction can be applied",AND(D10="[D] Client is not design responsible or other standard elements in the scope",G10>15%),"If Design is not included in the scope a maximum 15% reduction can be applied; please revise."),"")} | P10: =IFERROR(VLOOKUP(B10&"|"&C10&"|"&D10&"|"&"Duplicate",$AI$408:$AJ$508,1,FALSE),"") | Q10: =IFERROR(VLOOKUP(B10&"|"&C10&"|"&D10&"|"&"Duplicate",$AX$408:$AY$508,1,FALSE),"") | R10: =IFERROR(VLOOKUP(B10&"|"&C10&"|"&D10&"|"&"Duplicate",$BV$408:$BW$508,1,FALSE),"")
E11: {=_xlfn.IFS(LEFT(D11,3)="[D]","Decrease",LEFT(D11,3)="[I]","Increase",D11="","")} | F11: {=IFERROR(_xlfn.IFS(E11="Decrease",-1*G11,E11="Increase",G11),0)} -> 0 | G11: =IF(E11<>"",10%,0) -> 0 | H11: =IF($H$7=B11,VLOOKUP(C11,$Z$511:$AA$612,2,FALSE),0) -> 0 | I11: =IF($I$7=B11,VLOOKUP(C11,$AO$511:$AP$612,2,FALSE),0) -> 0 | J11: =IF($J$7=B11,VLOOKUP(C11,$BB$511:$BC$612,2,FALSE),0) -> 0 | K11: {=IFERROR(_xlfn.IFS(B11&"|"&C11&"|"&D11&"|"&"Duplicate"=P11,"This factor has already been used. Please revise.",B11&"|"&C11&"|"&D11&"|"&"Duplicate"=Q11,"This factor has already been used. Please revise.",B11&"|"&C11&"|"&D11&"|"&"Duplicate"=R11,"This factor has already been used. Please revise.",(H11<-0.3),"Please check reduction percentage since no more than -30% total reduction can be applied",(I11<-0.3),"Please check reduction percentage since no more than -30% total reduction can be applied",(J11<-0.3),"Please check reduction percentage since no more than -30% total reduction can be applied",AND(D11="[D] Client is not design responsible or other standard elements in the scope",G11>15%),"If Design is not included in the scope a maximum 15% reduction can be applied; please revise."),"")} | P11: =IFERROR(VLOOKUP(B11&"|"&C11&"|"&D11&"|"&"Duplicate",$AI$408:$AJ$508,1,FALSE),"") | Q11: =IFERROR(VLOOKUP(B11&"|"&C11&"|"&D11&"|"&"Duplicate",$AX$408:$AY$508,1,FALSE),"") | R11: =IFERROR(VLOOKUP(B11&"|"&C11&"|"&D11&"|"&"Duplicate",$BV$408:$BW$508,1,FALSE),"")
E12: {=_xlfn.IFS(LEFT(D12,3)="[D]","Decrease",LEFT(D12,3)="[I]","Increase",D12="","")} | F12: {=IFERROR(_xlfn.IFS(E12="Decrease",-1*G12,E12="Increase",G12),0)} -> 0 | G12: =IF(E12<>"",10%,0) -> 0 | H12: =IF($H$7=B12,VLOOKUP(C12,$Z$511:$AA$612,2,FALSE),0) -> 0 | I12: =IF($I$7=B12,VLOOKUP(C12,$AO$511:$AP$612,2,FALSE),0) -> 0 | J12: =IF($J$7=B12,VLOOKUP(C12,$BB$511:$BC$612,2,FALSE),0) -> 0 | K12: {=IFERROR(_xlfn.IFS(B12&"|"&C12&"|"&D12&"|"&"Duplicate"=P12,"This factor has already been used. Please revise.",B12&"|"&C12&"|"&D12&"|"&"Duplicate"=Q12,"This factor has already been used. Please revise.",B12&"|"&C12&"|"&D12&"|"&"Duplicate"=R12,"This factor has already been used. Please revise.",(H12<-0.3),"Please check reduction percentage since no more than -30% total reduction can be applied",(I12<-0.3),"Please check reduction percentage since no more than -30% total reduction can be applied",(J12<-0.3),"Please check reduction percentage since no more than -30% total reduction can be applied",AND(D12="[D] Client is not design responsible or other standard elements in the scope",G12>15%),"If Design is not included in the scope a maximum 15% reduction can be applied; please revise."),"")} | P12: =IFERROR(VLOOKUP(B12&"|"&C12&"|"&D12&"|"&"Duplicate",$AI$408:$AJ$508,1,FALSE),"") | Q12: =IFERROR(VLOOKUP(B12&"|"&C12&"|"&D12&"|"&"Duplicate",$AX$408:$AY$508,1,FALSE),"") | R12: =IFERROR(VLOOKUP(B12&"|"&C12&"|"&D12&"|"&"Duplicate",$BV$408:$BW$508,1,FALSE),"")
E13: {=_xlfn.IFS(LEFT(D13,3)="[D]","Decrease",LEFT(D13,3)="[I]","Increase",D13="","")} | F13: {=IFERROR(_xlfn.IFS(E13="Decrease",-1*G13,E13="Increase",G13),0)} -> 0 | G13: =IF(E13<>"",10%,0) -> 0 | H13: =IF($H$7=B13,VLOOKUP(C13,$Z$511:$AA$612,2,FALSE),0) -> 0 | I13: =IF($I$7=B13,VLOOKUP(C13,$AO$511:$AP$612,2,FALSE),0) -> 0 | J13: =IF($J$7=B13,VLOOKUP(C13,$BB$511:$BC$612,2,FALSE),0) -> 0 | K13: {=IFERROR(_xlfn.IFS(B13&"|"&C13&"|"&D13&"|"&"Duplicate"=P13,"This factor has already been used. Please revise.",B13&"|"&C13&"|"&D13&"|"&"Duplicate"=Q13,"This factor has already been used. Please revise.",B13&"|"&C13&"|"&D13&"|"&"Duplicate"=R13,"This factor has already been used. Please revise.",(H13<-0.3),"Please check reduction percentage since no more than -30% total reduction can be applied",(I13<-0.3),"Please check reduction percentage since no more than -30% total reduction can be applied",(J13<-0.3),"Please check reduction percentage since no more than -30% total reduction can be applied",AND(D13="[D] Client is not design responsible or other standard elements in the scope",G13>15%),"If Design is not included in the scope a maximum 15% reduction can be applied; please revise."),"")} | P13: =IFERROR(VLOOKUP(B13&"|"&C13&"|"&D13&"|"&"Duplicate",$AI$408:$AJ$508,1,FALSE),"") | Q13: =IFERROR(VLOOKUP(B13&"|"&C13&"|"&D13&"|"&"Duplicate",$AX$408:$AY$508,1,FALSE),"") | R13: =IFERROR(VLOOKUP(B13&"|"&C13&"|"&D13&"|"&"Duplicate",$BV$408:$BW$508,1,FALSE),"")
E14: {=_xlfn.IFS(LEFT(D14,3)="[D]","Decrease",LEFT(D14,3)="[I]","Increase",D14="","")} | F14: {=IFERROR(_xlfn.IFS(E14="Decrease",-1*G14,E14="Increase",G14),0)} -> 0 | G14: =IF(E14<>"",10%,0) -> 0 | H14: =IF($H$7=B14,VLOOKUP(C14,$Z$511:$AA$612,2,FALSE),0) -> 0 | I14: =IF($I$7=B14,VLOOKUP(C14,$AO$511:$AP$612,2,FALSE),0) -> 0 | J14: =IF($J$7=B14,VLOOKUP(C14,$BB$511:$BC$612,2,FALSE),0) -> 0 | K14: {=IFERROR(_xlfn.IFS(B14&"|"&C14&"|"&D14&"|"&"Duplicate"=P14,"This factor has already been used. Please revise.",B14&"|"&C14&"|"&D14&"|"&"Duplicate"=Q14,"This factor has already been used. Please revise.",B14&"|"&C14&"|"&D14&"|"&"Duplicate"=R14,"This factor has already been used. Please revise.",(H14<-0.3),"Please check reduction percentage since no more than -30% total reduction can be applied",(I14<-0.3),"Please check reduction percentage since no more than -30% total reduction can be applied",(J14<-0.3),"Please check reduction percentage since no more than -30% total reduction can be applied",AND(D14="[D] Client is not design responsible or other standard elements in the scope",G14>15%),"If Design is not included in the scope a maximum 15% reduction can be applied; please revise."),"")} | P14: =IFERROR(VLOOKUP(B14&"|"&C14&"|"&D14&"|"&"Duplicate",$AI$408:$AJ$508,1,FALSE),"") | Q14: =IFERROR(VLOOKUP(B14&"|"&C14&"|"&D14&"|"&"Duplicate",$AX$408:$AY$508,1,FALSE),"") | R14: =IFERROR(VLOOKUP(B14&"|"&C14&"|"&D14&"|"&"Duplicate",$BV$408:$BW$508,1,FALSE),"")
E15: {=_xlfn.IFS(LEFT(D15,3)="[D]","Decrease",LEFT(D15,3)="[I]","Increase",D15="","")} | F15: {=IFERROR(_xlfn.IFS(E15="Decrease",-1*G15,E15="Increase",G15),0)} -> 0 | G15: =IF(E15<>"",10%,0) -> 0 | H15: =IF($H$7=B15,VLOOKUP(C15,$Z$511:$AA$612,2,FALSE),0) -> 0 | I15: =IF($I$7=B15,VLOOKUP(C15,$AO$511:$AP$612,2,FALSE),0) -> 0 | J15: =IF($J$7=B15,VLOOKUP(C15,$BB$511:$BC$612,2,FALSE),0) -> 0 | K15: {=IFERROR(_xlfn.IFS(B15&"|"&C15&"|"&D15&"|"&"Duplicate"=P15,"This factor has already been used. Please revise.",B15&"|"&C15&"|"&D15&"|"&"Duplicate"=Q15,"This factor has already been used. Please revise.",B15&"|"&C15&"|"&D15&"|"&"Duplicate"=R15,"This factor has already been used. Please revise.",(H15<-0.3),"Please check reduction percentage since no more than -30% total reduction can be applied",(I15<-0.3),"Please check reduction percentage since no more than -30% total reduction can be applied",(J15<-0.3),"Please check reduction percentage since no more than -30% total reduction can be applied",AND(D15="[D] Client is not design responsible or other standard elements in the scope",G15>15%),"If Design is not included in the scope a maximum 15% reduction can be applied; please revise."),"")} | P15: =IFERROR(VLOOKUP(B15&"|"&C15&"|"&D15&"|"&"Duplicate",$AI$408:$AJ$508,1,FALSE),"") | Q15: =IFERROR(VLOOKUP(B15&"|"&C15&"|"&D15&"|"&"Duplicate",$AX$408:$AY$508,1,FALSE),"") | R15: =IFERROR(VLOOKUP(B15&"|"&C15&"|"&D15&"|"&"Duplicate",$BV$408:$BW$508,1,FALSE),"")
E16: {=_xlfn.IFS(LEFT(D16,3)="[D]","Decrease",LEFT(D16,3)="[I]","Increase",D16="","")} | F16: {=IFERROR(_xlfn.IFS(E16="Decrease",-1*G16,E16="Increase",G16),0)} -> 0 | G16: =IF(E16<>"",10%,0) -> 0 | H16: =IF($H$7=B16,VLOOKUP(C16,$Z$511:$AA$612,2,FALSE),0) -> 0 | I16: =IF($I$7=B16,VLOOKUP(C16,$AO$511:$AP$612,2,FALSE),0) -> 0 | J16: =IF($J$7=B16,VLOOKUP(C16,$BB$511:$BC$612,2,FALSE),0) -> 0 | K16: {=IFERROR(_xlfn.IFS(B16&"|"&C16&"|"&D16&"|"&"Duplicate"=P16,"This factor has already been used. Please revise.",B16&"|"&C16&"|"&D16&"|"&"Duplicate"=Q16,"This factor has already been used. Please revise.",B16&"|"&C16&"|"&D16&"|"&"Duplicate"=R16,"This factor has already been used. Please revise.",(H16<-0.3),"Please check reduction percentage since no more than -30% total reduction can be applied",(I16<-0.3),"Please check reduction percentage since no more than -30% total reduction can be applied",(J16<-0.3),"Please check reduction percentage since no more than -30% total reduction can be applied",AND(D16="[D] Client is not design responsible or other standard elements in the scope",G16>15%),"If Design is not included in the scope a maximum 15% reduction can be applied; please revise."),"")} | P16: =IFERROR(VLOOKUP(B16&"|"&C16&"|"&D16&"|"&"Duplicate",$AI$408:$AJ$508,1,FALSE),"") | Q16: =IFERROR(VLOOKUP(B16&"|"&C16&"|"&D16&"|"&"Duplicate",$AX$408:$AY$508,1,FALSE),"") | R16: =IFERROR(VLOOKUP(B16&"|"&C16&"|"&D16&"|"&"Duplicate",$BV$408:$BW$508,1,FALSE),"")
